Workbook

Sheet Dashboard
A1: Plan 70.3 Río — Seguimiento
A3: FTP actual (W): | B3: 205
A4: Meta 70.3: | B4: Sub 5:30
A5: Regla clave: | B5: Z2 real + tempo sostenido; Z4/Z5 dosificado
A7: Semana | B7: 1
A8: Horas plan (semana) | B8: =Semanas!E2 -> 11.083333
A9: Horas reales (semana) | B9: =Semanas!J2 -> 8.8666667
A10: % cumplimiento | B10: =Semanas!O2 -> 0.8

Sheet Plan diario
A1: Fecha | B1: Día | C1: Semana | D1: Inicio semana | E1: Fase | F1: Disciplina | G1: Sesión | H1: Objetivo | I1: Duración plan (min) | J1: Distancia plan | K1: Unidad | L1: Zona objetivo | M1: Indicaciones | N1: Estado | O1: Duración real (min) | P1: Distancia real | Q1: RPE | R1: FC media | S1: FC máx | T1: Potencia media (W) | U1: NP (W) | V1: Comentarios | W1: Min reales (auto)
A2: 46055 | B2: Lunes | C2: 1 | D2: 46055 | E2: Base específica (semana 1) | F2: Fuerza | G2: Fuerza tren inferior | H2: Fuerza | I2: 45 | L2: RPE 7–8 | M2: Sentadilla 4×4, RDL 3×5, step-ups 3×6/lad, core. Sin fallo. | N2: Hecho | O2: 45 | W2: =IF(OR($N2="Hecho",$N2="Parcial"),IF($O2="",0,$O2),0) -> 45
A3: 46055 | B3: Lunes | C3: 1 | D3: 46055 | E3: Base específica (semana 1) | F3: Running | G3: Z2 fácil (técnica) | H3: Base | I3: 40 | L3: Z2 | M3: Conversacional. Control de deriva. Cadencia 170–180. | N3: Hecho | O3: 39 | P3: 5.75 | R3: 136 | S3: 156 | T3: 276 | V3: Volviendo a la altura | W3: =IF(OR($N3="Hecho",$N3="Parcial"),IF($O3="",0,$O3),0) -> 39
A4: 46056 | B4: Martes | C4: 1 | D4: 46055 | E4: Base específica (semana 1) | F4: Natación | G4: Natación – calidad técnica/CSS | H4: Calidad | I4: 45 | J4: 2000 | K4: m | L4: Z2→CSS | M4: 300 suave + 6×50 técnica + 10×100 @CSS (20" rec) + 200 suave | N4: hecho | O4: 55 | P4: 2000 | R4: 133 | S4: 173 | W4: =IF(OR($N4="Hecho",$N4="Parcial"),IF($O4="",0,$O4),0) -> 55
A5: 46056 | B5: Martes | C5: 1 | D5: 46055 | E5: Base específica (semana 1) | F5: Bici | G5: Bici indoor – Z2 | H5: Base | I5: 60 | L5: Z2 (115–154W) | M5: Z2 estable. Cadencia 85–95. Ventilación/ventilador. | N5: Hecho | O5: 50 | P5: 23.39 | R5: 136 | S5: 158 | T5: 130 | W5: =IF(OR($N5="Hecho",$N5="Parcial"),IF($O5="",0,$O5),0) -> 50
A6: 46057 | B6: Miércoles | C6: 1 | D6: 46055 | E6: Base específica (semana 1) | F6: Running | G6: Running – Z2 + strides | H6: Base/técnica | I6: 45 | L6: Z2 + strides | M6: 30' Z2 + 6×20" strides (40" caminando). Control de deriva. | N6: hecho | O6: 40 | P6: 6.35 | R6: 137 | S6: 159 | W6: =IF(OR($N6="Hecho",$N6="Parcial"),IF($O6="",0,$O6),0) -> 40
A7: 46058 | B7: Jueves | C7: 1 | D7: 46055 | E7: Base específica (semana 1) | F7: Bici | G7: Bici indoor – Z2 | H7: Base | I7: 70 | L7: Z2 (115–154W) | M7: Z2 estricta, sin “apretar”. | N7: hecho | O7: 60 | P7: 24.6 | R7: 121 | S7: 168 | T7: 122 | W7: =IF(OR($N7="Hecho",$N7="Parcial"),IF($O7="",0,$O7),0) -> 60
A8: 46058 | B8: Jueves | C8: 1 | D8: 46055 | E8: Base específica (semana 1) | F8: Running | G8: Brick run – Z2 | H8: Base | I8: 20 | L8: Z2 | M8: Muy controlado; primer 5' muy suave. | N8: hecho | O8: 22 | P8: 4 | R8: 160 | S8: 171 | W8: =IF(OR($N8="Hecho",$N8="Parcial"),IF($O8="",0,$O8),0) -> 22
A9: 46059 | B9: Viernes | C9: 1 | D9: 46055 | E9: Base específica (semana 1) | F9: Natación | G9: Natación – simulación aguas abiertas (piscina) | H9: Aguas abiertas sim | I9: 45 | J9: 1800 | K9: m | L9: Z2 | M9: Continuo 1.5–1.8 km con 6–8 'sighting' cada 100–200m. | N9: hecho | O9: 31 | P9: 1450 | R9: 133 | S9: 148 | W9: =IF(OR($N9="Hecho",$N9="Parcial"),IF($O9="",0,$O9),0) -> 31
A10: 46059 | B10: Viernes | C10: 1 | D10: 46055 | E10: Base específica (semana 1) | F10: Fuerza | G10: Fuerza tren superior | H10: Fuerza | I10: 35 | L10: RPE 7–8 | M10: Empuje/tiron + core: press, remos, face pulls, planchas. Sin fatigar demasiado. | N10: Pendiente | W10: =IF(OR($N10="Hecho",$N10="Parcial"),IF($O10="",0,$O10),0) -> 0
A11: 46060 | B11: Sábado | C11: 1 | D11: 46055 | E11: Base específica (semana 1) | F11: Running | G11: Running largo – Z2 | H11: Base | I11: 80 | L11: Z2 | M11: Terreno plano. Conversacional. Técnica y economía. | N11: hecho | O11: 40 | P11: 2.34 | R11: 151 | S11: 174 | V11: 490 desnivel positivo | W11: =IF(OR($N11="Hecho",$N11="Parcial"),IF($O11="",0,$O11),0) -> 40
A12: 46061 | B12: Domingo | C12: 1 | D12: 46055 | E12: Base específica (semana 1) | F12: Bici | G12: Bici larga – Z2 + bloques Z3 | H12: Base/tempo | I12: 180 | L12: Z2 + Z3 (156–175W) | M12: Z2 + 2×8' Z3 (rec 6'). Nutrición 60–70g CH/h + sodio. | N12: hecho | O12: 150 | P12: 80.81 | R12: 157 | S12: 176 | T12: 164 | W12: =IF(OR($N12="Hecho",$N12="Parcial"),IF($O12="",0,$O12),0) -> 150
A13: 46062 | B13: Lunes | C13: 2 | D13: 46062 | E13: Base específica (semana 2) | F13: Fuerza | G13: Fuerza tren inferior | H13: Fuerza | I13: 45 | L13: RPE 7–8 | M13: Sentadilla 4×4, RDL 3×5, step-ups 3×6/lad, core. Sin fallo. | N13: hecho | O13: 30 | V13: hice yoga y estiramiento en vez de gym | W13: =IF(OR($N13="Hecho",$N13="Parcial"),IF($O13="",0,$O13),0) -> 30
A14: 46062 | B14: Lunes | C14: 2 | D14: 46062 | E14: Base específica (semana 2) | F14: Running | G14: Z2 fácil (técnica) | H14: Base | I14: 40 | L14: Z2 | M14: Conversacional. Control de deriva. Cadencia 170–180. | N14: Hecho | O14: 49 | P14: 7.47 | R14: 137 | S14: 149 | W14: =IF(OR($N14="Hecho",$N14="Parcial"),IF($O14="",0,$O14),0) -> 49
A15: 46063 | B15: Martes | C15: 2 | D15: 46062 | E15: Base específica (semana 2) | F15: Natación | G15: Natación – calidad técnica/CSS | H15: Calidad | I15: 45 | J15: 2000 | K15: m | L15: Z2→CSS | M15: 300 suave + 6×50 técnica + 10×100 @CSS (20" rec) + 200 suave | W15: =IF(OR($N15="Hecho",$N15="Parcial"),IF($O15="",0,$O15),0) -> 0
A16: 46063 | B16: Martes | C16: 2 | D16: 46062 | E16: Base específica (semana 2) | F16: Bici | G16: Bici indoor – Z2 | H16: Base | I16: 70 | L16: Z2 (115–154W) | M16: Z2 estable. Cadencia 85–95. Ventilación/ventilador. | N16: Hecho | O16: 60 | P16: 29.12 | R16: 133 | S16: 159 | T16: 135 | W16: =IF(OR($N16="Hecho",$N16="Parcial"),IF($O16="",0,$O16),0) -> 60
A17: 46064 | B17: Miércoles | C17: 2 | D17: 46062 | E17: Base específica (semana 2) | F17: Running | G17: Running – Z2 + strides | H17: Base/técnica | I17: 45 | L17: Z2 + strides | M17: 30' Z2 + 6×20" strides (40" caminando). Control de deriva. | N17: Hecho | O17: 40 | P17: 6.25 | R17: 139 | S17: 170 | W17: =IF(OR($N17="Hecho",$N17="Parcial"),IF($O17="",0,$O17),0) -> 40
A18: 46065 | B18: Jueves | C18: 2 | D18: 46062 | E18: Base específica (semana 2) | F18: Bici | G18: Bici indoor – Z2 | H18: Base | I18: 70 | L18: Z2 (115–154W) | M18: Z2 estricta, sin “apretar”. | N18: hecho | O18: 50 | P18: 18.86 | R18: 124 | S18: 172 | T18: 107 | W18: =IF(OR($N18="Hecho",$N18="Parcial"),IF($O18="",0,$O18),0) -> 50
A19: 46065 | B19: Jueves | C19: 2 | D19: 46062 | E19: Base específica (semana 2) | F19: Running | G19: Brick run – Z2 | H19: Base | I19: 20 | L19: Z2 | M19: Muy controlado; primer 5' muy suave. | N19: hecho | O19: 24 | P19: 4.18 | R19: 162 | S19: 171 | W19: =IF(OR($N19="Hecho",$N19="Parcial"),IF($O19="",0,$O19),0) -> 24
A20: 46066 | B20: Viernes | C20: 2 | D20: 46062 | E20: Base específica (semana 2) | F20: Natación | G20: Natación – simulación aguas abiertas (piscina) | H20: Aguas abiertas sim | I20: 45 | J20: 1800 | K20: m | L20: Z2 | M20: Continuo 1.5–1.8 km con 6–8 'sighting' cada 100–200m. | N20: hecho | O20: 39 | P20: 1500 | R20: 123 | S20: 160 | W20: =IF(OR($N20="Hecho",$N20="Parcial"),IF($O20="",0,$O20),0) -> 39
A21: 46066 | B21: Viernes | C21: 2 | D21: 46062 | E21: Base específica (semana 2) | F21: Fuerza | G21: Fuerza tren superior | H21: Fuerza | I21: 35 | L21: RPE 7–8 | M21: Empuje/tiron + core: press, remos, face pulls, planchas. Sin fatigar demasiado. | N21: Pendiente | W21: =IF(OR($N21="Hecho",$N21="Parcial"),IF($O21="",0,$O21),0) -> 0
A22: 46067 | B22: Sábado | C22: 2 | D22: 46062 | E22: Base específica (semana 2) | F22: Running | G22: Running largo – Z2 | H22: Base | I22: 85 | L22: Z2 | M22: Terreno plano. Conversacional. Técnica y economía. | N22: hecho | O22: 90 | P22: 12.91 | R22: 139 | S22: 151 | W22: =IF(OR($N22="Hecho",$N22="Parcial"),IF($O22="",0,$O22),0) -> 90
A23: 46068 | B23: Domingo | C23: 2 | D23: 46062 | E23: Base específica (semana 2) | F23: Bici | G23: Bici larga – Z2 + bloques Z3 | H23: Base/tempo | I23: 190 | L23: Z2 + Z3 (156–175W) | M23: Z2 + 2×10' Z3 (rec 6'). Nutrición igual. | N23: Pendiente | W23: =IF(OR($N23="Hecho",$N23="Parcial"),IF($O23="",0,$O23),0) -> 0
A24: 46069 | B24: Lunes | C24: 3 | D24: 46069 | E24: Base específica (semana 3) | F24: Fuerza | G24: Fuerza tren inferior | H24: Fuerza | I24: 45 | L24: RPE 7–8 | M24: Sentadilla 4×4, RDL 3×5, step-ups 3×6/lad, core. Sin fallo. | N24: hecho | O24: 52 | R24: 105 | S24: 153 | W24: =IF(OR($N24="Hecho",$N24="Parcial"),IF($O24="",0,$O24),0) -> 52
A25: 46069 | B25: Lunes | C25: 3 | D25: 46069 | E25: Base específica (semana 3) | F25: Running | G25: Z2 fácil (técnica) | H25: Base | I25: 40 | L25: Z2 | M25: Conversacional. Control de deriva. Cadencia 170–180. | N25: hecho | O25: 46 | P25: 6.95 | R25: 140 | S25: 154 | W25: =IF(OR($N25="Hecho",$N25="Parcial"),IF($O25="",0,$O25),0) -> 46
A26: 46070 | B26: Martes | C26: 3 | D26: 46069 | E26: Base específica (semana 3) | F26: Natación | G26: Natación – calidad técnica/CSS | H26: Calidad | I26: 45 | J26: 2000 | K26: m | L26: Z2→CSS | M26: 300 suave + 6×50 técnica + 10×100 @CSS (20" rec) + 200 suave | N26: Pendiente | W26: =IF(OR($N26="Hecho",$N26="Parcial"),IF($O26="",0,$O26),0) -> 0
A27: 46070 | B27: Martes | C27: 3 | D27: 46069 | E27: Base específica (semana 3) | F27: Bici | G27: Bici indoor – Z2 | H27: Base | I27: 60 | L27: Z2 (115–154W) | M27: Z2 estable. Cadencia 85–95. Ventilación/ventilador. | N27: hecho | O27: 50 | P27: 24.19 | R27: 126 | S27: 168 | T27: 136 | W27: =IF(OR($N27="Hecho",$N27="Parcial"),IF($O27="",0,$O27),0) -> 50
A28: 46071 | B28: Miércoles | C28: 3 | D28: 46069 | E28: Base específica (semana 3) | F28: Running | G28: Running – tempo controlado | H28: Tempo | I28: 60 | L28: Z3 (controlado) | M28: 15' Z2 + 3×8' Z3 (rec 3' Z2) + 10' suave. No entrar en Z5. | N28: Pendiente | W28: =IF(OR($N28="Hecho",$N28="Parcial"),IF($O28="",0,$O28),0) -> 0
A29: 46072 | B29: Jueves | C29: 3 | D29: 46069 | E29: Base específica (semana 3) | F29: Bici | G29: Bici indoor – Z2 | H29: Base | I29: 70 | L29: Z2 (115–154W) | M29: Z2 estricta, sin “apretar”. | N29: hecho | O29: 47 | R29: 136 | S29: 158 | W29: =IF(OR($N29="Hecho",$N29="Parcial"),IF($O29="",0,$O29),0) -> 47
A30: 46072 | B30: Jueves | C30: 3 | D30: 46069 | E30: Base específica (semana 3) | F30: Running | G30: Brick run – Z2 | H30: Base | I30: 20 | L30: Z2 | M30: Muy controlado; primer 5' muy suave. | N30: hecho | O30: 24 | P30: 4.13 | R30: 164 | S30: 172 | W30: =IF(OR($N30="Hecho",$N30="Parcial"),IF($O30="",0,$O30),0) -> 24
A31: 46073 | B31: Viernes | C31: 3 | D31: 46069 | E31: Base específica (semana 3) | F31: Natación | G31: Natación – simulación aguas abiertas (piscina) | H31: Aguas abiertas sim | I31: 45 | J31: 1800 | K31: m | L31: Z2 | M31: Continuo 1.5–1.8 km con 6–8 'sighting' cada 100–200m. | N31: hecho | O31: 51 | P31: 2500 | R31: 141 | S31: 162 | W31: =IF(OR($N31="Hecho",$N31="Parcial"),IF($O31="",0,$O31),0) -> 51
A32: 46073 | B32: Viernes | C32: 3 | D32: 46069 | E32: Base específica (semana 3) | F32: Fuerza | G32: Fuerza tren superior | H32: Fuerza | I32: 35 | L32: RPE 7–8 | M32: Empuje/tiron + core: press, remos, face pulls, planchas. Sin fatigar demasiado. | N32: hecho | O32: 31 | V32: yoga en vez de fuerza por dolores y recuperacion | W32: =IF(OR($N32="Hecho",$N32="Parcial"),IF($O32="",0,$O32),0) -> 31
A33: 46074 | B33: Sábado | C33: 3 | D33: 46069 | E33: Base específica (semana 3) | F33: Running | G33: Running largo – Z2 | H33: Base | I33: 90 | L33: Z2 | M33: Terreno plano. Conversacional. Técnica y economía. | N33: hecho | O33: 90 | P33: 12.89 | R33: 145 | S33: 160 | W33: =IF(OR($N33="Hecho",$N33="Parcial"),IF($O33="",0,$O33),0) -> 90
A34: 46075 | B34: Domingo | C34: 3 | D34: 46069 | E34: Base específica (semana 3) | F34: Bici | G34: Bici larga – Z2 + bloques Z3 | H34: Base/tempo | I34: 200 | L34: Z2 + Z3 (156–175W) | M34: Z2 + 3×8' Z3 (rec 6'). Última hora sólida. | N34: hecho | O34: 180 | P34: 85.76 | R34: 150 | S34: 172 | T34: 131 | W34: =IF(OR($N34="Hecho",$N34="Parcial"),IF($O34="",0,$O34),0) -> 180
A35: 46076 | B35: Lunes | C35: 4 | D35: 46076 | E35: Descarga (-20–25%) | F35: Fuerza | G35: Fuerza tren inferior | H35: Fuerza | I35: 45 | L35: RPE 7–8 | M35: Sentadilla 4×4, RDL 3×5, step-ups 3×6/lad, core. Sin fallo. | N35: hecho | O35: 51 | R35: 77 | S35: 124 | W35: =IF(OR($N35="Hecho",$N35="Parcial"),IF($O35="",0,$O35),0) -> 51
A36: 46076 | B36: Lunes | C36: 4 | D36: 46076 | E36: Descarga (-20–25%) | F36: Running | G36: Z2 fácil (técnica) | H36: Base | I36: 30 | L36: Z2 | M36: Conversacional. Control de deriva. Cadencia 170–180. | N36: hecho | O36: 30 | P36: 4.3 | R36: 123 | S36: 136 | W36: =IF(OR($N36="Hecho",$N36="Parcial"),IF($O36="",0,$O36),0) -> 30
A37: 46077 | B37: Martes | C37: 4 | D37: 46076 | E37: Descarga (-20–25%) | F37: Natación | G37: Natación – suave técnica | H37: Recuperación | I37: 40 | J37: 1600 | K37: m | L37: Z1–Z2 | M37: Técnica + continuo fácil | N37: hecho | O37: 46 | P37: 1400 | R37: 118 | S37: 166 | W37: =IF(OR($N37="Hecho",$N37="Parcial"),IF($O37="",0,$O37),0) -> 46
A38: 46077 | B38: Martes | C38: 4 | D38: 46076 | E38: Descarga (-20–25%) | F38: Bici | G38: Bici indoor – Z2 suave | H38: Recuperación | I38: 50 | L38: Z1–Z2 | M38: Muy fácil. | N38: Pendiente | W38: =IF(OR($N38="Hecho",$N38="Parcial"),IF($O38="",0,$O38),0) -> 0
A39: 46078 | B39: Miércoles | C39: 4 | D39: 46076 | E39: Descarga (-20–25%) | F39: Running | G39: Running – Z2 fácil + 4 strides | H39: Recuperación | I39: 35 | L39: Z1–Z2 | M39: 25' fácil + 4×20" strides suaves. | N39: Pendiente | W39: =IF(OR($N39="Hecho",$N39="Parcial"),IF($O39="",0,$O39),0) -> 0
A40: 46079 | B40: Jueves | C40: 4 | D40: 46076 | E40: Descarga (-20–25%) | F40: Bici | G40: Bici indoor – Z2 | H40: Recuperación | I40: 55 | L40: Z2 | M40: Z2 cómodo. | N40: hecho | O40: 50 | P40: 20.46 | R40: 112 | S40: 140 | T40: 112 | W40: =IF(OR($N40="Hecho",$N40="Parcial"),IF($O40="",0,$O40),0) -> 50
...

Sheet Semanas
A1: Semana | B1: Inicio | C1: Fin | D1: Fase | E1: Horas plan | F1: Horas plan Nat | G1: Horas plan Bici | H1: Horas plan Run | I1: Horas plan Fuerza | J1: Horas reales | K1: Horas reales Nat | L1: Horas reales Bici | M1: Horas reales Run | N1: Horas reales Fuerza | O1: % cumplimiento
A2: 1 | B2: 46055 | C2: 46061 | D2: Base específica (semana 1) | E2: =SUMIFS('Plan diario'!$I$2:$I$295,'Plan diario'!$D$2:$D$295,$B2)/60 -> 11.083333 | F2: =SUMIFS('Plan diario'!$I$2:$I$295,'Plan diario'!$D$2:$D$295,$B2,'Plan diario'!$F$2:$F$295,"Natación")/60 -> 1.5 | G2: =SUMIFS('Plan diario'!$I$2:$I$295,'Plan diario'!$D$2:$D$295,$B2,'Plan diario'!$F$2:$F$295,"Bici")/60 -> 5.1666667 | H2: =SUMIFS('Plan diario'!$I$2:$I$295,'Plan diario'!$D$2:$D$295,$B2,'Plan diario'!$F$2:$F$295,"Running")/60 -> 3.0833333 | I2: =SUMIFS('Plan diario'!$I$2:$I$295,'Plan diario'!$D$2:$D$295,$B2,'Plan diario'!$F$2:$F$295,"Fuerza")/60 -> 1.3333333 | J2: =SUMIFS('Plan diario'!$W$2:$W$295,'Plan diario'!$D$2:$D$295,$B2)/60 -> 8.8666667 | K2: =SUMIFS('Plan diario'!$W$2:$W$295,'Plan diario'!$D$2:$D$295,$B2,'Plan diario'!$F$2:$F$295,"Natación")/60 -> 1.4333333 | L2: =SUMIFS('Plan diario'!$W$2:$W$295,'Plan diario'!$D$2:$D$295,$B2,'Plan diario'!$F$2:$F$295,"Bici")/60 -> 4.3333333 | M2: =SUMIFS('Plan diario'!$W$2:$W$295,'Plan diario'!$D$2:$D$295,$B2,'Plan diario'!$F$2:$F$295,"Running")/60 -> 2.35 | N2: =SUMIFS('Plan diario'!$W$2:$W$295,'Plan diario'!$D$2:$D$295,$B2,'Plan diario'!$F$2:$F$295,"Fuerza")/60 -> 0.75 | O2: =IF($E2=0,"",$J2/$E2) -> 0.8
A3: 2 | B3: 46062 | C3: 46068 | D3: Base específica (semana 2) | E3: =SUMIFS('Plan diario'!$I$2:$I$295,'Plan diario'!$D$2:$D$295,$B3)/60 -> 11.5 | F3: =SUMIFS('Plan diario'!$I$2:$I$295,'Plan diario'!$D$2:$D$295,$B3,'Plan diario'!$F$2:$F$295,"Natación")/60 -> 1.5 | G3: =SUMIFS('Plan diario'!$I$2:$I$295,'Plan diario'!$D$2:$D$295,$B3,'Plan diario'!$F$2:$F$295,"Bici")/60 -> 5.5 | H3: =SUMIFS('Plan diario'!$I$2:$I$295,'Plan diario'!$D$2:$D$295,$B3,'Plan diario'!$F$2:$F$295,"Running")/60 -> 3.1666667 | I3: =SUMIFS('Plan diario'!$I$2:$I$295,'Plan diario'!$D$2:$D$295,$B3,'Plan diario'!$F$2:$F$295,"Fuerza")/60 -> 1.3333333 | J3: =SUMIFS('Plan diario'!$W$2:$W$295,'Plan diario'!$D$2:$D$295,$B3)/60 -> 6.3666667 | K3: =SUMIFS('Plan diario'!$W$2:$W$295,'Plan diario'!$D$2:$D$295,$B3,'Plan diario'!$F$2:$F$295,"Natación")/60 -> 0.65 | L3: =SUMIFS('Plan diario'!$W$2:$W$295,'Plan diario'!$D$2:$D$295,$B3,'Plan diario'!$F$2:$F$295,"Bici")/60 -> 1.8333333 | M3: =SUMIFS('Plan diario'!$W$2:$W$295,'Plan diario'!$D$2:$D$295,$B3,'Plan diario'!$F$2:$F$295,"Running")/60 -> 3.3833333 | N3: =SUMIFS('Plan diario'!$W$2:$W$295,'Plan diario'!$D$2:$D$295,$B3,'Plan diario'!$F$2:$F$295,"Fuerza")/60 -> 0.5 | O3: =IF($E3=0,"",$J3/$E3) -> 0.55362319
A4: 3 | B4: 46069 | C4: 46075 | D4: Base específica (semana 3) | E4: =SUMIFS('Plan diario'!$I$2:$I$295,'Plan diario'!$D$2:$D$295,$B4)/60 -> 11.833333 | F4: =SUMIFS('Plan diario'!$I$2:$I$295,'Plan diario'!$D$2:$D$295,$B4,'Plan diario'!$F$2:$F$295,"Natación")/60 -> 1.5 | G4: =SUMIFS('Plan diario'!$I$2:$I$295,'Plan diario'!$D$2:$D$295,$B4,'Plan diario'!$F$2:$F$295,"Bici")/60 -> 5.5 | H4: =SUMIFS('Plan diario'!$I$2:$I$295,'Plan diario'!$D$2:$D$295,$B4,'Plan diario'!$F$2:$F$295,"Running")/60 -> 3.5 | I4: =SUMIFS('Plan diario'!$I$2:$I$295,'Plan diario'!$D$2:$D$295,$B4,'Plan diario'!$F$2:$F$295,"Fuerza")/60 -> 1.3333333 | J4: =SUMIFS('Plan diario'!$W$2:$W$295,'Plan diario'!$D$2:$D$295,$B4)/60 -> 9.5166667 | K4: =SUMIFS('Plan diario'!$W$2:$W$295,'Plan diario'!$D$2:$D$295,$B4,'Plan diario'!$F$2:$F$295,"Natación")/60 -> 0.85 | L4: =SUMIFS('Plan diario'!$W$2:$W$295,'Plan diario'!$D$2:$D$295,$B4,'Plan diario'!$F$2:$F$295,"Bici")/60 -> 4.6166667 | M4: =SUMIFS('Plan diario'!$W$2:$W$295,'Plan diario'!$D$2:$D$295,$B4,'Plan diario'!$F$2:$F$295,"Running")/60 -> 2.6666667 | N4: =SUMIFS('Plan diario'!$W$2:$W$295,'Plan diario'!$D$2:$D$295,$B4,'Plan diario'!$F$2:$F$295,"Fuerza")/60 -> 1.3833333 | O4: =IF($E4=0,"",$J4/$E4) -> 0.80422535
A5: 4 | B5: 46076 | C5: 46082 | D5: Descarga (-20–25%) | E5: =SUMIFS('Plan diario'!$I$2:$I$295,'Plan diario'!$D$2:$D$295,$B5)/60 -> 9.4166667 | F5: =SUMIFS('Plan diario'!$I$2:$I$295,'Plan diario'!$D$2:$D$295,$B5,'Plan diario'!$F$2:$F$295,"Natación")/60 -> 1.3333333 | G5: =SUMIFS('Plan diario'!$I$2:$I$295,'Plan diario'!$D$2:$D$295,$B5,'Plan diario'!$F$2:$F$295,"Bici")/60 -> 4.25 | H5: =SUMIFS('Plan diario'!$I$2:$I$295,'Plan diario'!$D$2:$D$295,$B5,'Plan diario'!$F$2:$F$295,"Running")/60 -> 2.5 | I5: =SUMIFS('Plan diario'!$I$2:$I$295,'Plan diario'!$D$2:$D$295,$B5,'Plan diario'!$F$2:$F$295,"Fuerza")/60 -> 1.3333333 | J5: =SUMIFS('Plan diario'!$W$2:$W$295,'Plan diario'!$D$2:$D$295,$B5)/60 -> 7.05 | K5: =SUMIFS('Plan diario'!$W$2:$W$295,'Plan diario'!$D$2:$D$295,$B5,'Plan diario'!$F$2:$F$295,"Natación")/60 -> 1.6666667 | L5: =SUMIFS('Plan diario'!$W$2:$W$295,'Plan diario'!$D$2:$D$295,$B5,'Plan diario'!$F$2:$F$295,"Bici")/60 -> 2.45 | M5: =SUMIFS('Plan diario'!$W$2:$W$295,'Plan diario'!$D$2:$D$295,$B5,'Plan diario'!$F$2:$F$295,"Running")/60 -> 1.7333333 | N5: =SUMIFS('Plan diario'!$W$2:$W$295,'Plan diario'!$D$2:$D$295,$B5,'Plan diario'!$F$2:$F$295,"Fuerza")/60 -> 1.2 | O5: =IF($E5=0,"",$J5/$E5) -> 0.74867257
A6: 5 | B6: 46083 | C6: 46089 | D6: Base avanzada | E6: =SUMIFS('Plan diario'!$I$2:$I$295,'Plan diario'!$D$2:$D$295,$B6)/60 -> 12.25 | F6: =SUMIFS('Plan diario'!$I$2:$I$295,'Plan diario'!$D$2:$D$295,$B6,'Plan diario'!$F$2:$F$295,"Natación")/60 -> 1.5 | G6: =SUMIFS('Plan diario'!$I$2:$I$295,'Plan diario'!$D$2:$D$295,$B6,'Plan diario'!$F$2:$F$295,"Bici")/60 -> 5.75 | H6: =SUMIFS('Plan diario'!$I$2:$I$295,'Plan diario'!$D$2:$D$295,$B6,'Plan diario'!$F$2:$F$295,"Running")/60 -> 3.6666667 | I6: =SUMIFS('Plan diario'!$I$2:$I$295,'Plan diario'!$D$2:$D$295,$B6,'Plan diario'!$F$2:$F$295,"Fuerza")/60 -> 1.3333333 | J6: =SUMIFS('Plan diario'!$W$2:$W$295,'Plan diario'!$D$2:$D$295,$B6)/60 -> 4.6833333 | K6: =SUMIFS('Plan diario'!$W$2:$W$295,'Plan diario'!$D$2:$D$295,$B6,'Plan diario'!$F$2:$F$295,"Natación")/60 -> 0.8 | L6: =SUMIFS('Plan diario'!$W$2:$W$295,'Plan diario'!$D$2:$D$295,$B6,'Plan diario'!$F$2:$F$295,"Bici")/60 -> 2.05 | M6: =SUMIFS('Plan diario'!$W$2:$W$295,'Plan diario'!$D$2:$D$295,$B6,'Plan diario'!$F$2:$F$295,"Running")/60 -> 1.8333333 | N6: =SUMIFS('Plan diario'!$W$2:$W$295,'Plan diario'!$D$2:$D$295,$B6,'Plan diario'!$F$2:$F$295,"Fuerza")/60 -> 0 | O6: =IF($E6=0,"",$J6/$E6) -> 0.38231293
A7: 6 | B7: 46090 | C7: 46096 | D7: Base avanzada | E7: =SUMIFS('Plan diario'!$I$2:$I$295,'Plan diario'!$D$2:$D$295,$B7)/60 -> 12.583333 | F7: =SUMIFS('Plan diario'!$I$2:$I$295,'Plan diario'!$D$2:$D$295,$B7,'Plan diario'!$F$2:$F$295,"Natación")/60 -> 1.5 | G7: =SUMIFS('Plan diario'!$I$2:$I$295,'Plan diario'!$D$2:$D$295,$B7,'Plan diario'!$F$2:$F$295,"Bici")/60 -> 5.9166667 | H7: =SUMIFS('Plan diario'!$I$2:$I$295,'Plan diario'!$D$2:$D$295,$B7,'Plan diario'!$F$2:$F$295,"Running")/60 -> 3.8333333 | I7: =SUMIFS('Plan diario'!$I$2:$I$295,'Plan diario'!$D$2:$D$295,$B7,'Plan diario'!$F$2:$F$295,"Fuerza")/60 -> 1.3333333 | J7: =SUMIFS('Plan diario'!$W$2:$W$295,'Plan diario'!$D$2:$D$295,$B7)/60 -> 9.45 | K7: =SUMIFS('Plan diario'!$W$2:$W$295,'Plan diario'!$D$2:$D$295,$B7,'Plan diario'!$F$2:$F$295,"Natación")/60 -> 0.53333333 | L7: =SUMIFS('Plan diario'!$W$2:$W$295,'Plan diario'!$D$2:$D$295,$B7,'Plan diario'!$F$2:$F$295,"Bici")/60 -> 4.7666667 | M7: =SUMIFS('Plan diario'!$W$2:$W$295,'Plan diario'!$D$2:$D$295,$B7,'Plan diario'!$F$2:$F$295,"Running")/60 -> 2.7666667 | N7: =SUMIFS('Plan diario'!$W$2:$W$295,'Plan diario'!$D$2:$D$295,$B7,'Plan diario'!$F$2:$F$295,"Fuerza")/60 -> 1.3833333 | O7: =IF($E7=0,"",$J7/$E7) -> 0.75099338
A8: 7 | B8: 46097 | C8: 46103 | D8: Mini‑taper (pre‑olímpico) | E8: =SUMIFS('Plan diario'!$I$2:$I$295,'Plan diario'!$D$2:$D$295,$B8)/60 -> 8.5833333 | F8: =SUMIFS('Plan diario'!$I$2:$I$295,'Plan diario'!$D$2:$D$295,$B8,'Plan diario'!$F$2:$F$295,"Natación")/60 -> 1.0833333 | G8: =SUMIFS('Plan diario'!$I$2:$I$295,'Plan diario'!$D$2:$D$295,$B8,'Plan diario'!$F$2:$F$295,"Bici")/60 -> 3.6666667 | H8: =SUMIFS('Plan diario'!$I$2:$I$295,'Plan diario'!$D$2:$D$295,$B8,'Plan diario'!$F$2:$F$295,"Running")/60 -> 2.5 | I8: =SUMIFS('Plan diario'!$I$2:$I$295,'Plan diario'!$D$2:$D$295,$B8,'Plan diario'!$F$2:$F$295,"Fuerza")/60 -> 1.3333333 | J8: =SUMIFS('Plan diario'!$W$2:$W$295,'Plan diario'!$D$2:$D$295,$B8)/60 -> 3.2666667 | K8: =SUMIFS('Plan diario'!$W$2:$W$295,'Plan diario'!$D$2:$D$295,$B8,'Plan diario'!$F$2:$F$295,"Natación")/60 -> 0.05 | L8: =SUMIFS('Plan diario'!$W$2:$W$295,'Plan diario'!$D$2:$D$295,$B8,'Plan diario'!$F$2:$F$295,"Bici")/60 -> 1.6666667 | M8: =SUMIFS('Plan diario'!$W$2:$W$295,'Plan diario'!$D$2:$D$295,$B8,'Plan diario'!$F$2:$F$295,"Running")/60 -> 1.55 | N8: =SUMIFS('Plan diario'!$W$2:$W$295,'Plan diario'!$D$2:$D$295,$B8,'Plan diario'!$F$2:$F$295,"Fuerza")/60 -> 0 | O8: =IF($E8=0,"",$J8/$E8) -> 0.38058252
A9: 8 | B9: 46104 | C9: 46110 | D9: Carrera Olímpico (25‑Mar) | E9: =SUMIFS('Plan diario'!$I$2:$I$295,'Plan diario'!$D$2:$D$295,$B9)/60 -> 10.083333 | F9: =SUMIFS('Plan diario'!$I$2:$I$295,'Plan diario'!$D$2:$D$295,$B9,'Plan diario'!$F$2:$F$295,"Natación")/60 -> 1.25 | G9: =SUMIFS('Plan diario'!$I$2:$I$295,'Plan diario'!$D$2:$D$295,$B9,'Plan diario'!$F$2:$F$295,"Bici")/60 -> 3.1666667 | H9: =SUMIFS('Plan diario'!$I$2:$I$295,'Plan diario'!$D$2:$D$295,$B9,'Plan diario'!$F$2:$F$295,"Running")/60 -> 1.6666667 | I9: =SUMIFS('Plan diario'!$I$2:$I$295,'Plan diario'!$D$2:$D$295,$B9,'Plan diario'!$F$2:$F$295,"Fuerza")/60 -> 1 | J9: =SUMIFS('Plan diario'!$W$2:$W$295,'Plan diario'!$D$2:$D$295,$B9)/60 -> 0.58333333 | K9: =SUMIFS('Plan diario'!$W$2:$W$295,'Plan diario'!$D$2:$D$295,$B9,'Plan diario'!$F$2:$F$295,"Natación")/60 -> 0 | L9: =SUMIFS('Plan diario'!$W$2:$W$295,'Plan diario'!$D$2:$D$295,$B9,'Plan diario'!$F$2:$F$295,"Bici")/60 -> 0 | M9: =SUMIFS('Plan diario'!$W$2:$W$295,'Plan diario'!$D$2:$D$295,$B9,'Plan diario'!$F$2:$F$295,"Running")/60 -> 0.58333333 | N9: =SUMIFS('Plan diario'!$W$2:$W$295,'Plan diario'!$D$2:$D$295,$B9,'Plan diario'!$F$2:$F$295,"Fuerza")/60 -> 0 | O9: =IF($E9=0,"",$J9/$E9) -> 0.05785124
A10: 9 | B10: 46111 | C10: 46117 | D10: Build 1 | E10: =SUMIFS('Plan diario'!$I$2:$I$295,'Plan diario'!$D$2:$D$295,$B10)/60 -> 12.75 | F10: =SUMIFS('Plan diario'!$I$2:$I$295,'Plan diario'!$D$2:$D$295,$B10,'Plan diario'!$F$2:$F$295,"Natación")/60 -> 1.5 | G10: =SUMIFS('Plan diario'!$I$2:$I$295,'Plan diario'!$D$2:$D$295,$B10,'Plan diario'!$F$2:$F$295,"Bici")/60 -> 5.9166667 | H10: =SUMIFS('Plan diario'!$I$2:$I$295,'Plan diario'!$D$2:$D$295,$B10,'Plan diario'!$F$2:$F$295,"Running")/60 -> 4 | I10: =SUMIFS('Plan diario'!$I$2:$I$295,'Plan diario'!$D$2:$D$295,$B10,'Plan diario'!$F$2:$F$295,"Fuerza")/60 -> 1.3333333 | J10: =SUMIFS('Plan diario'!$W$2:$W$295,'Plan diario'!$D$2:$D$295,$B10)/60 -> 8.55 | K10: =SUMIFS('Plan diario'!$W$2:$W$295,'Plan diario'!$D$2:$D$295,$B10,'Plan diario'!$F$2:$F$295,"Natación")/60 -> 0 | L10: =SUMIFS('Plan diario'!$W$2:$W$295,'Plan diario'!$D$2:$D$295,$B10,'Plan diario'!$F$2:$F$295,"Bici")/60 -> 5 | M10: =SUMIFS('Plan diario'!$W$2:$W$295,'Plan diario'!$D$2:$D$295,$B10,'Plan diario'!$F$2:$F$295,"Running")/60 -> 3.05 | N10: =SUMIFS('Plan diario'!$W$2:$W$295,'Plan diario'!$D$2:$D$295,$B10,'Plan diario'!$F$2:$F$295,"Fuerza")/60 -> 0.5 | O10: =IF($E10=0,"",$J10/$E10) -> 0.67058824
A11: 10 | B11: 46118 | C11: 46124 | D11: Build 1 | E11: =SUMIFS('Plan diario'!$I$2:$I$295,'Plan diario'!$D$2:$D$295,$B11)/60 -> 13 | F11: =SUMIFS('Plan diario'!$I$2:$I$295,'Plan diario'!$D$2:$D$295,$B11,'Plan diario'!$F$2:$F$295,"Natación")/60 -> 1.5 | G11: =SUMIFS('Plan diario'!$I$2:$I$295,'Plan diario'!$D$2:$D$295,$B11,'Plan diario'!$F$2:$F$295,"Bici")/60 -> 6.1666667 | H11: =SUMIFS('Plan diario'!$I$2:$I$295,'Plan diario'!$D$2:$D$295,$B11,'Plan diario'!$F$2:$F$295,"Running")/60 -> 4 | I11: =SUMIFS('Plan diario'!$I$2:$I$295,'Plan diario'!$D$2:$D$295,$B11,'Plan diario'!$F$2:$F$295,"Fuerza")/60 -> 1.3333333 | J11: =SUMIFS('Plan diario'!$W$2:$W$295,'Plan diario'!$D$2:$D$295,$B11)/60 -> 10.6 | K11: =SUMIFS('Plan diario'!$W$2:$W$295,'Plan diario'!$D$2:$D$295,$B11,'Plan diario'!$F$2:$F$295,"Natación")/60 -> 0.61666667 | L11: =SUMIFS('Plan diario'!$W$2:$W$295,'Plan diario'!$D$2:$D$295,$B11,'Plan diario'!$F$2:$F$295,"Bici")/60 -> 5.4666667 | M11: =SUMIFS('Plan diario'!$W$2:$W$295,'Plan diario'!$D$2:$D$295,$B11,'Plan diario'!$F$2:$F$295,"Running")/60 -> 3.8333333 | N11: =SUMIFS('Plan diario'!$W$2:$W$295,'Plan diario'!$D$2:$D$295,$B11,'Plan diario'!$F$2:$F$295,"Fuerza")/60 -> 0.68333333 | O11: =IF($E11=0,"",$J11/$E11) -> 0.81538462
A12: 11 | B12: 46125 | C12: 46131 | D12: Build 1 | E12: =SUMIFS('Plan diario'!$I$2:$I$295,'Plan diario'!$D$2:$D$295,$B12)/60 -> 13.25 | F12: =SUMIFS('Plan diario'!$I$2:$I$295,'Plan diario'!$D$2:$D$295,$B12,'Plan diario'!$F$2:$F$295,"Natación")/60 -> 1.5 | G12: =SUMIFS('Plan diario'!$I$2:$I$295,'Plan diario'!$D$2:$D$295,$B12,'Plan diario'!$F$2:$F$295,"Bici")/60 -> 6.3333333 | H12: =SUMIFS('Plan diario'!$I$2:$I$295,'Plan diario'!$D$2:$D$295,$B12,'Plan diario'!$F$2:$F$295,"Running")/60 -> 4.0833333 | I12: =SUMIFS('Plan diario'!$I$2:$I$295,'Plan diario'!$D$2:$D$295,$B12,'Plan diario'!$F$2:$F$295,"Fuerza")/60 -> 1.3333333 | J12: =SUMIFS('Plan diario'!$W$2:$W$295,'Plan diario'!$D$2:$D$295,$B12)/60 -> 5.7833333 | K12: =SUMIFS('Plan diario'!$W$2:$W$295,'Plan diario'!$D$2:$D$295,$B12,'Plan diario'!$F$2:$F$295,"Natación")/60 -> 0.53333333 | L12: =SUMIFS('Plan diario'!$W$2:$W$295,'Plan diario'!$D$2:$D$295,$B12,'Plan diario'!$F$2:$F$295,"Bici")/60 -> 1 | M12: =SUMIFS('Plan diario'!$W$2:$W$295,'Plan diario'!$D$2:$D$295,$B12,'Plan diario'!$F$2:$F$295,"Running")/60 -> 3.5 | N12: =SUMIFS('Plan diario'!$W$2:$W$295,'Plan diario'!$D$2:$D$295,$B12,'Plan diario'!$F$2:$F$295,"Fuerza")/60 -> 0.75 | O12: =IF($E12=0,"",$J12/$E12) -> 0.43647799
A13: 12 | B13: 46132 | C13: 46138 | D13: Descarga | E13: =SUMIFS('Plan diario'!$I$2:$I$295,'Plan diario'!$D$2:$D$295,$B13)/60 -> 10.083333 | F13: =SUMIFS('Plan diario'!$I$2:$I$295,'Plan diario'!$D$2:$D$295,$B13,'Plan diario'!$F$2:$F$295,"Natación")/60 -> 1.3333333 | G13: =SUMIFS('Plan diario'!$I$2:$I$295,'Plan diario'!$D$2:$D$295,$B13,'Plan diario'!$F$2:$F$295,"Bici")/60 -> 1.9166667 | H13: =SUMIFS('Plan diario'!$I$2:$I$295,'Plan diario'!$D$2:$D$295,$B13,'Plan diario'!$F$2:$F$295,"Running")/60 -> 3 | I13: =SUMIFS('Plan diario'!$I$2:$I$295,'Plan diario'!$D$2:$D$295,$B13,'Plan diario'!$F$2:$F$295,"Fuerza")/60 -> 1.3333333 | J13: =SUMIFS('Plan diario'!$W$2:$W$295,'Plan diario'!$D$2:$D$295,$B13)/60 -> 4.0516667 | K13: =SUMIFS('Plan diario'!$W$2:$W$295,'Plan diario'!$D$2:$D$295,$B13,'Plan diario'!$F$2:$F$295,"Natación")/60 -> 0.53333333 | L13: =SUMIFS('Plan diario'!$W$2:$W$295,'Plan diario'!$D$2:$D$295,$B13,'Plan diario'!$F$2:$F$295,"Bici")/60 -> 0 | M13: =SUMIFS('Plan diario'!$W$2:$W$295,'Plan diario'!$D$2:$D$295,$B13,'Plan diario'!$F$2:$F$295,"Running")/60 -> 0 | N13: =SUMIFS('Plan diario'!$W$2:$W$295,'Plan diario'!$D$2:$D$295,$B13,'Plan diario'!$F$2:$F$295,"Fuerza")/60 -> 0.73333333 | O13: =IF($E13=0,"",$J13/$E13) -> 0.40181818
... A28: 27 | B28: 46237 | C28: 46243 | D28: Race week (70.3 Río) | E28: =SUMIFS('Plan diario'!$I$2:$I$295,'Plan diario'!$D$2:$D$295,$B28)/60 -> 9.0833333 | F28: =SUMIFS('Plan diario'!$I$2:$I$295,'Plan diario'!$D$2:$D$295,$B28,'Plan diario'!$F$2:$F$295,"Natación")/60 -> 1 | G28: =SUMIFS('Plan diario'!$I$2:$I$295,'Plan diario'!$D$2:$D$295,$B28,'Plan diario'!$F$2:$F$295,"Bici")/60 -> 1.0833333 | H28: =SUMIFS('Plan diario'!$I$2:$I$295,'Plan diario'!$D$2:$D$295,$B28,'Plan diario'!$F$2:$F$295,"Running")/60 -> 1.1666667 | I28: =SUMIFS('Plan diario'!$I$2:$I$295,'Plan diario'!$D$2:$D$295,$B28,'Plan diario'!$F$2:$F$295,"Fuerza")/60 -> 0 | J28: =SUMIFS('Plan diario'!$W$2:$W$295,'Plan diario'!$D$2:$D$295,$B28)/60 -> 0 | K28: =SUMIFS('Plan diario'!$W$2:$W$295,'Plan diario'!$D$2:$D$295,$B28,'Plan diario'!$F$2:$F$295,"Natación")/60 -> 0 | L28: =SUMIFS('Plan diario'!$W$2:$W$295,'Plan diario'!$D$2:$D$295,$B28,'Plan diario'!$F$2:$F$295,"Bici")/60 -> 0 | M28: =SUMIFS('Plan diario'!$W$2:$W$295,'Plan diario'!$D$2:$D$295,$B28,'Plan diario'!$F$2:$F$295,"Running")/60 -> 0 | N28: =SUMIFS('Plan diario'!$W$2:$W$295,'Plan diario'!$D$2:$D$295,$B28,'Plan diario'!$F$2:$F$295,"Fuerza")/60 -> 0 | O28: =IF($E28=0,"",$J28/$E28) -> 0

Sheet Tests & Resultados
A1: Fecha | B1: Prueba | C1: Resultado | D1: Unidad | E1: Notas
A2: 46054 | B2: 5K running | C2: 0.017037037 | D2: hh:mm:ss | E2: Mejor marca informada
A3: 46054 | B3: 10K running | C3: 0.037037037 | D3: hh:mm:ss | E3: Mejor marca informada
A4: 46054 | B4: 21K running | C4: 0.088888889 | D4: hh:mm:ss | E4: Mejor marca informada
A5: 46054 | B5: FTP bici | C5: 205 | D5: W | E5: Test FTP indoor (20')
A6: 46054 | B6: 1K natación | C6: 0.01369213 | D6: hh:mm:ss | E6: Piscina

Sheet Zonas & Notas
A1: Zonas (Bici) — basadas en FTP
A3: FTP (W) | B3: 205
A4: Z1 | B4: < 56% | C4: < 115 W
A5: Z2 | B5: 56–75% | C5: 115–154 W
A6: Z3 | B6: 76–90% | C6: 156–185 W
A7: Z4 | B7: 91–105% | C7: 187–215 W
A9: Regla deriva (running): | B9: Si en Z2 la FC sube >5–6% manteniendo ritmo similar → bajar ritmo / revisar calor, hidratación y fatiga.
A12: Nutrición base en bici (entrenos largos): | B12: 70–90 g CH/h (subir gradual), 500–900 mg sodio/h, 500–750 ml/h (más si calor).

Sheet Plan Rio ajustado
A1: Plan agresivo 70.3 Río de Janeiro — 30 abril a 9 agosto 2026
A2: Objetivo: 5:31 h. Estructura: 10–11 h/semana en builds, descargas estratégicas, foco en cramp-proofing, nutrición y carrera post-bici.
A4: Fecha | B4: Día | C4: Semana plan | D4: Fase | E4: Disciplina | F4: Sesión | G4: Min | H4: Horas | I4: Volumen objetivo | J4: Intensidad/Zona | K4: Detalle | L4: Nutrición/Hidratación | M4: Objetivo | N4: Estado | O4: Duración real | P4: Notas
A5: 46142 | B5: Jueves | C5: 0 | D5: Recuperación post-Neiva + reset | E5: Bici | F5: Rodillo recuperación | G5: 45 | H5: =G5/60 -> 0.75 | I5: — | J5: Z1–Z2 / 115–145 W | K5: Cadencia 90–95, sin bloquear piernas; termina fresco. | L5: Agua + 300–500 mg sodio si sudas mucho. | M5: Bajar tono muscular post-calambres. | N5: Planificado
A6: 46142 | B6: Jueves | C6: 0 | D6: Recuperación post-Neiva + reset | E6: Movilidad | F6: Movilidad + liberación | G6: 15 | H6: =G6/60 -> 0.25 | I6: — | J6: Suave | K6: Gemelos, sóleo, flexores de cadera, glúteo medio; respiración nasal 5'. | L6: Cena con carbohidrato + proteína. | M6: Recuperar rango articular. | N6: Planificado
A7: 46143 | B7: Viernes | C7: 0 | D7: Recuperación post-Neiva + reset | E7: Natación | F7: Técnica y calma en agua | G7: 45 | H7: =G7/60 -> 0.75 | I7: 1.600–1.800 m | J7: Z1–Z2 | K7: 300 suave + 8×50 técnica + 6×100 cómodo + 200 suave. Practica exhalación completa. | L7: No necesitas gel; hidrátate normal. | M7: Eliminar pánico/adrenalina inicial. | N7: Planificado
A8: 46143 | B8: Viernes | C8: 0 | D8: Recuperación post-Neiva + reset | E8: Fuerza | F8: Prehab calambres | G8: 20 | H8: =G8/60 -> 0.33333333 | I8: — | J8: RPE 5–6 | K8: 3×12 elevación gemelo recto + 3×12 sóleo rodilla flexionada + puente glúteo + plancha. | L8: Proteína en la siguiente comida. | M8: Activar pantorrilla y core sin fatigar. | N8: Planificado
A9: 46144 | B9: Sábado | C9: 0 | D9: Recuperación post-Neiva + reset | E9: Running | F9: Z2 fácil + strides | G9: 50 | H9: =G9/60 -> 0.83333333 | I9: 7–8 km aprox | J9: Z2 + 6×20” | K9: 40' conversacional + 6×20” alegres con 60” suave; sin buscar ritmo. | L9: Agua; si hace calor 300–500 mg sodio. | M9: Reiniciar carrera sin agravar calambres. | N9: Planificado
A10: 46145 | B10: Domingo | C10: 0 | D10: Recuperación post-Neiva + reset | E10: Bici | F10: Bici Z2 de reinicio | G10: 90 | H10: =G10/60 -> 1.5 | I10: 45–50 km rodillo/ruta | J10: Z2 / 125–150 W | K10: Mantén presión constante. Últimos 15' a 150–155 W si HR controlada. | L10: 40–60 g CH/h + 500–700 ml/h. | M10: Volver a volumen sin intensidad excesiva. | N10: Planificado
A11: 46145 | B11: Domingo | C11: 0 | D11: Recuperación post-Neiva + reset | E11: Running | F11: Brick muy fácil | G11: 15 | H11: =G11/60 -> 0.25 | I11: 2–2,5 km | J11: Z1–Z2 | K11: Primeros 5' casi trote; cadencia corta y técnica. | L11: Nada extra. | M11: Revisar si aparece amago de calambre. | N11: Planificado
A12: 46146 | B12: Lunes | C12: 1 | D12: Build 1 – técnica + Z2 | E12: Movilidad | F12: Descanso activo | G12: 20 | H12: =G12/60 -> 0.33333333 | I12: — | J12: Z0 | K12: Movilidad general + 10' caminata. Sueño prioritario. | L12: Hidratar y comer normal. | M12: Absorber recuperación. | N12: Planificado
A13: 46147 | B13: Martes | C13: 1 | D13: Build 1 – técnica + Z2 | E13: Natación | F13: CSS test controlado | G13: 50 | H13: =G13/60 -> 0.83333333 | I13: 2.000 m | J13: Test + técnica | K13: 400 suave + 4×50 técnica + test 400m + 6' rec + test 200m + suave. No salir a tope los primeros 100m. | L13: Comida con CH 2–3 h antes. | M13: Definir ritmo CSS real y control mental. | N13: Planificado
A14: 46147 | B14: Martes | C14: 1 | D14: Build 1 – técnica + Z2 | E14: Bici | F14: Rodillo Z2 | G14: 55 | H14: =G14/60 -> 0.91666667 | I14: — | J14: Z2 / 125–150 W | K14: Cadencia 85–95. Sin pasar de Z2. | L14: 30–45 g CH/h si vas en ayunas o cansado. | M14: Base aeróbica limpia. | N14: Planificado
A15: 46148 | B15: Miércoles | C15: 1 | D15: Build 1 – técnica + Z2 | E15: Running | F15: Tempo controlado | G15: 60 | H15: =G15/60 -> 1 | I15: 9–10 km aprox | J15: Z2 + Z3 | K15: 15' Z2 + 4×6' a ritmo cómodo-fuerte (rec 2') + 10' suave. | L15: Agua; si calor, sodio. | M15: Subir umbral sin cargar demasiado. | N15: Planificado
A16: 46148 | B16: Miércoles | C16: 1 | D16: Build 1 – técnica + Z2 | E16: Fuerza | F16: Fuerza tren inferior | G16: 35 | H16: =G16/60 -> 0.58333333 | I16: — | J16: RPE 7 | K16: Sentadilla o prensa 4×4, RDL 3×6, step-up 3×6/lad, gemelo pesado 4×6, core. | L16: Proteína 25–35 g post. | M16: Economía y resistencia neuromuscular. | N16: Planificado
... A165: 46243 | B165: Domingo | C165: 14 | D165: Race week | E165: Carrera | F165: IRONMAN 70.3 Río | G165: 331 | H165: =G165/60 -> 5.5166667 | I165: 1.9 km + 90 km + 21.1 km | J165: Plan de carrera | K165: Swim 43–45'; T1 4'; bike 2:43–2:49 a 150–162 W; T2 2–3'; run 1:55–2:00 con salida conservadora. | L165: Desayuno 3–4 h antes. Bici 85–95 g CH/h + 700–1000 mg sodio/h. Run 60–75 g CH/h + sodio/agua por aid stations. | M165: Meta 5:31 ejecutando sin calambres. | N165: Planificado

Sheet Resumen 70.3
A1: Plan 70.3 Río — resumen ejecutivo
A2: Fecha carrera oficial | B2: 46243 | C2: Objetivo total | D2: 5:31:00 | E2: Semana inicio plan | F2: 46142
A3: Split objetivo | B3: Tiempo | C3: Ritmo/Velocidad | D3: Criterio | E3: Riesgo principal | F3: Control
A4: Natación 1.9 km | B4: 0:43–0:45 | C4: 2:16–2:22/100m | D4: Neiva 1.5 km en 34.5' proyecta ~43.7' | E4: Adrenalina/contacto | F4: Primeros 200m muy controlados + exhalar
A5: T1 | B5: 0:04 | C5: — | D5: Simple y limpia | E5: Apuro | F5: Checklist fijo
A6: Bici 90 km | B6: 2:43–2:49 | C6: 32.0–33.1 km/h | D6: Neiva 40 km a 32.3 km/h; sostener sin quemar run | E6: Sobrebike + calor | F6: 150–162 W por FTP 205, sin picos
A7: T2 | B7: 0:02–0:03 | C7: — | D7: Zapatos, gorra, gel | E7: Desorden | F7: Rutina ensayada
A8: Running 21.1 km | B8: 1:55–2:00 | C8: 5:27–5:41/km | D8: Necesita durabilidad post-bici; salir conservador | E8: Calambres | F8: Primeros 8 km a 5:45–5:55 y progresar
A10: Lectura del registro | B10: Conclusión
A11: Consistencia | B11: Ya hay base desde febrero, con semanas cercanas a 9–10.6 h y muchas sesiones reales.
A12: Punto fuerte 1 | B12: Bici: 40 km a 32.3 km/h con FC 162 muestra buen techo; falta sostener 90 km sin comprometer run.
A13: Punto fuerte 2 | B13: Running: pudiste retomar 5:50/km pese a calambres; hay motor, falta resistencia neuromuscular post-bici.
A14: Debilidad 1 | B14: Natación: el ritmo da para el objetivo, pero el riesgo es mental/contacto/FC, no solo físico.
A15: Debilidad 2 | B15: Calambres: trabajarlos como problema de fatiga neuromuscular + calor + pacing + nutrición, no solo sal.
A16: Debilidad 3 | B16: Volumen de natación bajo vs 70.3; mínimo 2 sesiones/semana, 3 en semanas clave.
A18: Resumen semanal
A19: Semana | B19: Inicio | C19: Fase | D19: Horas plan | E19: Sesiones | F19: Foco
A20: 0 | B20: 46142 | C20: Recuperación post-Neiva + reset | D20: 4.6666667 | E20: 7 | F20: Recuperar calambres y reiniciar sin fatiga.
A21: 1 | B21: 46146 | C21: Build 1 – técnica + Z2 | D21: 10.083333 | E21: 12 | F21: CSS, Z2 y primer brick largo controlado.
A22: 2 | B22: 46153 | C22: Build 1 – subida controlada | D22: 10.583333 | E22: 11 | F22: Subir race power y correr más largo.
A23: 3 | B23: 46160 | C23: Descarga + técnica | D23: 8.3333333 | E23: 11 | F23: Descarga para asimilar.
A24: 4 | B24: 46167 | C24: Build 2 – fuerza-resistencia | D24: 10.916667 | E24: 11 | F24: Sweet spot + bici larga 85–90 km.
A25: 5 | B25: 46174 | C25: Build 2 – umbral aeróbico | D25: 10.916667 | E25: 11 | F25: Nutrición alta y continuo 1.9k.
A26: 6 | B26: 46181 | C26: Build 2 – brick progresivo | D26: 11 | E26: 11 | F26: Bici específica 2×30' + run largo.
A27: 7 | B27: 46188 | C27: Descarga | D27: 8.4166667 | E27: 11 | F27: Descarga y chequeo de race power.
A28: 8 | B28: 46195 | C28: Específico 70.3 – race power | D28: 10.833333 | E28: 11 | F28: Bloques 70.3 y brick a ritmo.
A29: 9 | B29: 46202 | C29: Específico 70.3 – nutrición | D29: 10.916667 | E29: 11 | F29: Ensayo nutrición 85–90 g CH/h.
A30: 10 | B30: 46209 | C30: Específico 70.3 – fatiga controlada | D30: 11 | E30: 11 | F30: Fatiga controlada sin pasar 11 h.
A31: 11 | B31: 46216 | C31: Pico + simulación 70.3 | D31: 10.75 | E31: 10 | F31: Simulación clave recortada.
... A34: 14 | B34: 46237 | C34: Race week | D34: 9.6833333 | E34: 11 | F34: Race week.

Sheet Nutrición y pacing
A1: Nutrición, hidratación y pacing 70.3
A2: Área | B2: Recomendación | C2: Cómo aplicarlo en este plan | D2: Notas
A3: Carbohidratos en sesiones >2.5 h | B3: Subir gradualmente hasta 85–95 g CH/h en bici y 60–75 g CH/h corriendo. | C3: Practicar en todos los domingos desde junio; registrar tolerancia GI. | D3: Usar mezcla glucosa/fructosa si pasas de 60 g/h.
A4: Sodio y fluidos | B4: Base: 600–1000 mg sodio/h y 500–900 ml/h, ajustado por sudor/calor. | C4: Pésate antes/después de sesiones largas para estimar pérdida; no buscar ganar peso durante sesión. | D4: En calor/humedad puede subir necesidad; evitar sobrehidratarse sin sodio.
A5: Desayuno carrera | B5: 3–4 h antes: 2–3 g CH/kg, bajo en fibra/grasas, probado antes. | C5: Mismo desayuno en simulación del 19/07. | D5: No estrenar alimentos.
A6: Bici carrera | B6: Comer desde los primeros 10–15 min. Objetivo 85–95 g CH/h. | C6: Ejemplo/hora: 1 botella 60 g CH + 1 gel 25 g + sodio. | D6: No esperar hambre; alarmas cada 10–15 min.
A7: Run carrera | B7: 60–75 g CH/h si el estómago tolera; agua en puestos. | C7: Gel cada 20–25 min + sorbos de agua; sodio según calor. | D7: Si hay náusea, bajar ritmo 2–3 min y volver al plan.
A8: Calambres | B8: Tratar como fatiga neuromuscular + pacing + calor + combustible, no solo sal. | C8: Bici sin picos, fuerza gemelo/sóleo, bricks, calor controlado. | D8: Si persisten o son severos, revisar con médico/deportólogo.
A9: Heat acclimation | B9: 10–14 días antes: exposiciones suaves al calor, idealmente 45–60 min en sesiones fáciles. | C9: Del 20/07 al 03/08 usa rodillo/run fácil con calor controlado o calor pasivo corto. | D9: Nunca deshidratarse a propósito; detener si mareo/escalofrío.
A10: Recuperación diaria | B10: Proteína 1.4–2.0 g/kg/d; CH alto en días clave, menor en descansos. | C10: Priorizar cena post-brick y sueño 7.5–9 h. | D10: No hacer déficit calórico agresivo en build.
A11: Pacing natación | B11: Primeros 200m demasiado fáciles; exhalación continua; buscar pies tranquilos. | C11: Practicar sighting y contacto en piscina cuando se pueda. | D11: Tu limitante en Neiva fue el susto/FC, no la capacidad de nadar 1.5k.
A12: Pacing bici | B12: Primeros 30 km 150–158 W; km 30–75 155–162 W; últimos 15 km solo subir si HR/estómago OK. | C12: Prohibidos picos >180 W salvo seguridad. | D12: Con FTP 205, es aprox 73–79% FTP.
A13: Pacing run | B13: Km 1–8 a 5:45–5:55; km 9–16 a 5:35–5:45; km 17–21 según piernas. | C13: Si aparece calambre: 60–120 s más suave, cadencia alta, zancada corta. | D13: No perseguir ritmo si la FC se dispara por calor.

Sheet Fuentes
A1: Tema | B1: Fuente | C1: URL
A2: Fecha/carrera oficial | B2: IRONMAN 70.3 Rio de Janeiro / registro oficial | C2: https://regbra1.ironman.com/event/2026-ironman-703-rio-de-janeiro
A3: Información del evento/curso | B3: IRONMAN 70.3 Rio de Janeiro | C3: https://www.ironman.com/races/im703-rio-de-janeiro
A4: Entrenamiento polarizado/intensidad | B4: Oliveira et al. 2024, Sports Medicine Open/PMC | C4: https://pmc.ncbi.nlm.nih.gov/articles/PMC11329428/
A5: Taper | B5: Bosquet et al. 2007, Effects of tapering on performance meta-analysis | C5: https://pubmed.ncbi.nlm.nih.gov/17762369/
A6: Taper revisión reciente | B6: Wang et al. 2023, PLOS ONE | C6: https://journals.plos.org/plosone/article?id=10.1371/journal.pone.0282838
A7: Carbohidratos durante ejercicio | B7: Jeukendrup 2014, Carbohydrate Intake During Exercise | C7: https://pmc.ncbi.nlm.nih.gov/articles/PMC4008807/
A8: Carbohidratos para competición | B8: Burke et al. 2011, Journal of Sports Sciences/PubMed | C8: https://pubmed.ncbi.nlm.nih.gov/21660838/
A9: Hidratación/fluidos | B9: ACSM Position Stand: Exercise and Fluid Replacement | C9: https://pubmed.ncbi.nlm.nih.gov/17277604/
A10: Calambres asociados al ejercicio | B10: Miller et al. 2010, Exercise-Associated Muscle Cramps | C10: https://pmc.ncbi.nlm.nih.gov/articles/PMC3445088/
A11: Heat acclimation | B11: Racinais et al. 2015, Consensus recommendations | C11: https://pubmed.ncbi.nlm.nih.gov/25943653/
A12: Fuerza y economía | B12: Luckin-Baldwin et al. 2021, Strength Training Improves Exercise Economy | C12: https://pubmed.ncbi.nlm.nih.gov/33571959/
A13: Proteína diaria | B13: ISSN Position Stand: Protein and Exercise | C13: https://pubmed.ncbi.nlm.nih.gov/28642676/
